{"error_id": "eb525df5-450a-487e-82a3-3470c45b8b1a", "timestamp": "2025-07-11T11:19:01.914370", "severity": "high", "category": "trading", "error_type": "insufficient_funds", "message": "Test insufficient funds error", "exception": "Test insufficient funds error", "stack_trace": "Traceback (most recent call last):\n  File \"/data/data/com.termux/files/home/algua/test_error_handling.py\", line 32, in test_error_manager\n    raise ValueError(\"Test insufficient funds error\")\nValueError: Test insufficient funds error\n", "module": "__main__", "function": "test_error_manager", "line_number": 34, "user_id": "test_user", "session_id": null, "strategy_id": null, "order_id": null, "symbol": "AAPL", "hostname": "localhost", "process_id": 29214, "thread_id": 539829140776, "memory_usage": 30470144, "cpu_usage": 0.0, "metadata": {"order_id": "12345", "amount": 1000.0}, "related_errors": [], "recoverable": true, "recovery_attempted": false, "recovery_successful": null, "recovery_actions": []}
{"error_id": "803a40c6-55da-404d-b2c9-09f63bc31422", "timestamp": "2025-07-11T11:19:01.915213", "severity": "medium", "category": "network", "error_type": "connection_timeout", "message": "API connection timeout", "exception": "API connection timeout", "stack_trace": "Traceback (most recent call last):\n  File \"/data/data/com.termux/files/home/algua/test_error_handling.py\", line 47, in test_error_manager\n    raise ConnectionError(\"API connection timeout\")\nConnectionError: API connection timeout\n", "module": "__main__", "function": "test_error_manager", "line_number": 49, "user_id": null, "session_id": null, "strategy_id": null, "order_id": null, "symbol": null, "hostname": "localhost", "process_id": 29214, "thread_id": 539829140776, "memory_usage": 30470144, "cpu_usage": 0.0, "metadata": {"endpoint": "https://api.example.com", "timeout": 30}, "related_errors": [], "recoverable": true, "recovery_attempted": false, "recovery_successful": null, "recovery_actions": []}
{"error_id": "7aa843da-3694-439a-8003-bae238dbb9c7", "timestamp": "2025-07-11T11:19:01.915754", "severity": "critical", "category": "risk", "error_type": "risk_limit_breach", "message": "Risk limit exceeded", "exception": "Risk limit exceeded", "stack_trace": "Traceback (most recent call last):\n  File \"/data/data/com.termux/files/home/algua/test_error_handling.py\", line 59, in test_error_manager\n    raise TradingError(\nerror_handling.error_manager.TradingError: Risk limit exceeded\n", "module": "__main__", "function": "test_error_manager", "line_number": 66, "user_id": null, "session_id": null, "strategy_id": null, "order_id": null, "symbol": null, "hostname": "localhost", "process_id": 29214, "thread_id": 539829140776, "memory_usage": 30470144, "cpu_usage": 0.0, "metadata": {"current_exposure": 150000, "limit": 100000}, "related_errors": [], "recoverable": true, "recovery_attempted": false, "recovery_successful": null, "recovery_actions": []}
{"error_id": "577ce340-e1a9-42c6-ad53-99fbeec44693", "timestamp": "2025-07-11T11:21:34.937279", "severity": "high", "category": "trading", "error_type": "insufficient_funds", "message": "Test error", "exception": "Test error", "stack_trace": "Traceback (most recent call last):\n  File \"/data/data/com.termux/files/home/algua/test_error_handling_simple.py\", line 30, in test_basic_functionality\n    raise ValueError(\"Test error\")\nValueError: Test error\n", "module": "__main__", "function": "test_basic_functionality", "line_number": 32, "user_id": null, "session_id": null, "strategy_id": null, "order_id": null, "symbol": null, "hostname": "localhost", "process_id": 30713, "thread_id": 480644889896, "memory_usage": 30146560, "cpu_usage": 0.0, "metadata": {}, "related_errors": [], "recoverable": true, "recovery_attempted": false, "recovery_successful": null, "recovery_actions": []}
{"error_id": "02b65d8d-5e3e-4b66-a33f-fa1c1b907175", "timestamp": "2025-07-11T11:28:37.060177", "severity": "high", "category": "trading", "error_type": "insufficient_funds", "message": "Test error", "exception": "Test error", "stack_trace": "Traceback (most recent call last):\n  File \"/data/data/com.termux/files/home/algua/test_error_handling_simple.py\", line 30, in test_basic_functionality\n    raise ValueError(\"Test error\")\nValueError: Test error\n", "module": "__main__", "function": "test_basic_functionality", "line_number": 32, "user_id": null, "session_id": null, "strategy_id": null, "order_id": null, "symbol": null, "hostname": "localhost", "process_id": 3511, "thread_id": 529472482600, "memory_usage": 30478336, "cpu_usage": 0.0, "metadata": {}, "related_errors": [], "recoverable": true, "recovery_attempted": false, "recovery_successful": null, "recovery_actions": []}
